Workbook

Sheet Sheet1
A1: No | B1: Username | C1: Type | D1: Tier | E1: Keterangan Lokasi | F1: Social Media | G1: Followers | H1: Kategory | I1: Nama PIC | J1: Contact PIC | K1: Rate Card
A2: 1 | B2: elianarsyd | C2: Makro | D2: 1 | E2: Surabaya | F2: Tiktok | G2: 117K | H2: Career&self development | I2: Admin | J2: 8561542352 | K2: Tiktok | L2: 1,300,000
K3: IG Reels | L3: 1,200,000
K4: Bundling (mirroring) | L4: 2,000,000
A5: 2 | B5: jennitanuwijayaaa | C5: Nano | F5: Tiktok | G5: 3.523 | H5: Entrepreneurship/Business Content | K5: Tiktok
K6: IG Reels
K7: Bundling (mirroring)
A8: 3 | B8: nbstory_ | C8: Mikro | D8: 1 | E8: Jakarta | F8: Tiktok | G8: 11,6K | H8: Lifestyle & Relationship | I8: Belby | J8: 85117142556 | K8: Tiktok | L8: 650
K9: IG Reels | L9: -
K10: Bundling (mirroring) | L10: -
A11: 4 | B11: kevinmillenio | C11: Makro | D11: 1 | E11: Gading Serpong | F11: Tiktok | G11: 372,8K | H11: Entertainment | I11: Triska | J11: 8132131350 | K11: Tiktok | L11: 35,000,000
K12: IG Reels | L12: 35,000,000
K13: Bundling (mirroring) | L13: 20,000,000
A14: 5 | B14: kesyasunnn | C14: Makro | D14: 1 | E14: Gading Serpong | F14: Tiktok | G14: 189,7K | H14: Entertainment | I14: Triska | J14: 8132131350 | K14: Tiktok | L14: 12,000,000
K15: IG Reels | L15: 12,000,000
K16: Bundling (mirroring) | L16: 8,000,000
A17: 6 | B17: femimaringka | C17: Makro | D17: 1 | E17: Gading Serpong | F17: Tiktok | G17: 138,4K | H17: Entertainment | I17: Triska | J17: 8132131350 | K17: Tiktok | L17: 12,000,000
K18: IG Reels | L18: 12,000,000
K19: Bundling (mirroring) | L19: 8,000,000
A20: 7 | B20: firamaringka | C20: Makro | D20: 1 | E20: Gading Serpong | F20: Tiktok | G20: 360,1K | H20: Entertainment | I20: Triska | J20: 8132131350 | K20: Tiktok | L20: 25,000,000
K21: IG Reels | L21: 20,000,000
K22: Bundling (mirroring) | L22: 11,000,000
A23: 8 | B23: tituschrst | C23: Makro | D23: 1 | E23: Gading Serpong | F23: Tiktok | G23: 169,8K | H23: Entertainment | I23: Triska | J23: 8132131350 | K23: Tiktok | L23: 12,000,000
K24: IG Reels | L24: 10,000,000
K25: Bundling (mirroring) | L25: 5,000,000
A26: 9 | B26: trio.reog | C26: Makro | D26: 1 | E26: Gading Serpong | F26: Tiktok | G26: 318,3K | H26: Entertainment | I26: Triska | J26: 8132131350 | K26: Tiktok | L26: 7,000,000
K27: IG Reels | L27: 7,000,000
K28: Bundling (mirroring) | L28: 3,500,000
A29: 10 | B29: misyandpiyo | C29: Mikro | D29: 1 | E29: Gading Serpong | F29: Tiktok | G29: 259,6K | H29: Family & Parenting | I29: Admin | J29: 85770028814 | K29: Tiktok | L29: 7,000,000
K30: IG Reels | L30: 7,000,000
K31: Bundling (mirroring) | L31: 3,500,000
A32: 11 | B32: dinna_ashari15 | C32: Mega (but in 2026 viewers drop) | D32: 2 | E32: Palembang | F32: Tiktok | G32: 2,3M | H32: Family & Parenting | I32: Admin | J32: 82246769579 | K32: Tiktok | L32: 1,000,000
K33: IG Reels | L33: 1,000,000
K34: Bundling (mirroring) | L34: 1,850,000
A35: 12 | B35: rapundel | C35: Makro | D35: 3 | E35: Tasikmalaya | F35: Tiktok | G35: 481,3K | H35: Education | I35: Team | J35: 89658881718 | K35: Tiktok | L35: 6,000,000
K36: IG Reels | L36: 7,000,000
K37: Bundling (mirroring) | L37: -
A38: 13 | B38: shaaaqy | C38: Makro | D38: 1 | E38: Jakarta | F38: Tiktok | G38: 835K | H38: Lifestyle & Entertainment | I38: Natasha (manager) | J38: 85176767622 | K38: Tiktok | L38: 20,000,000
K39: IG Reels | L39: 12,000,000
K40: Bundling (mirroring) | L40: 24,000,000
...

Sheet Sheet2
A1: No | B1: Username | C1: Social Media | D1: Followers | E1: General Brief | F1: PIC | G1: No PIC | H1: Tier | I1: Rate Card
A2: 1 | B2: wkwkland_real | C2: Instagram | D2: 513K | F2: admin wkwkland | G2: 85156953076 | H2: Nasional | I2: IG Story | J2: 300
I3: Reels | J3: 2,000,000
I4: Feeds | J4: 1,500,000
A5: 2 | B5: bestie.genk | C5: Instagram | D5: 497K | E5: Akun Gossip | F5: admin bestiegenk | G5: 82186101480 | H5: Nasional | I5: 1 IGS | J5: 180
I6: 2 IGS | J6: 360
I7: 3 IGS | J7: 430
A8: 3 | B8: bestiegenk.closefriend | C8: Instagram | D8: 359K | E8: Akun Gossip | F8: admin bestiegenk | G8: 82186101480 | H8: Nasional | I8: 1 IGS | J8: 150
I9: 2 IGS | J9: 340
I10: 3 IGS | J10: 390
A11: 4 | B11: lambe_turah | C11: Instagram | D11: 12M | E11: Akun Gossip | F11: admin | G11: 81328616092 | H11: Nasional | I11: Feeds | J11: 15,000,000
I12: Reels | J12: 20,000,000
I13: IG Story Photo | J13: 2,500,000
A14: 5 | B14: lambeturah_official | C14: Instagram | D14: 2M | E14: Akun Gossip | F14: admin | G14: 81328616092 | H14: Nasional | I14: Feeds | J14: 3,000,000
I15: Reels | J15: 6,000,000
I16: IG Story Photo | J16: 1,000,000
A17: 6 | B17: ngakakkocak | C17: Instagram | D17: 11M | E17: Akun Meme/Lucu | F17: admin | G17: 81388308870 | H17: Nasional | I17: Feeds | J17: 6,000,000
I18: Reels | J18: 6,500,000
I19: IG Story | J19: 2,000,000
A20: 7 | B20: ngakaksehat | C20: Instagram | D20: 4,5M | E20: Akun Meme/Lucu | F20: admin | G20: 81388308870 | H20: Nasional | I20: Feeds | J20: 3,000,000
I21: Reels | J21: 4,000,000
I22: IG Story | J22: 1,500,000
A23: 8 | B23: misterkomedi | C23: Instagram | D23: 1M | E23: Akun Meme/Lucu | F23: admin | G23: 81388308870 | H23: Nasional | I23: Feeds | J23: 600
I24: Reels | J24: 600
I25: IG Story | J25: 400
A26: 9 | B26: indoviral8 | C26: Instagram | D26: 629K | E26: Akun Meme/Lucu, Viral | F26: admin | G26: 81388308870 | H26: Nasional | I26: Feeds | J26: 300
I27: Reels | J27: 400
I28: IG Story | J28: 200
A29: 10 | B29: awreceh.id | C29: Instagram | D29: 4M | E29: Akun Meme/Lucu, Viral | F29: saragih media | G29: 85892487894 | H29: Nasional | I29: Feeds | J29: 700
I30: Reels | J30: 700
I31: IG Story | J31: 400
A32: 11 | B32: kegoblogan.unfaedah | C32: Instagram | D32: 2,1M | E32: Akun Meme/Lucu, Viral | F32: saragih media | G32: 85892487894 | H32: Nasional | I32: Feeds | J32: 400
I33: Reels | J33: 400
I34: IG Story | J34: 200
A35: 12 | B35: kegobloganunfaedah | C35: Instagram | D35: 1,2M | E35: Akun Meme/Lucu, Viral | F35: saragih media | G35: 85892487894 | H35: Nasional | I35: Feeds | J35: 200
I36: Reels | J36: 200
I37: IG Story | J37: -
A38: 13 | B38: kegoblogan.unfaedahh_ | C38: Instagram | D38: 1M | E38: Akun Meme/Lucu, Viral | F38: saragih media | G38: 85892487894 | H38: Nasional | I38: Feeds | J38: 150
I39: Reels | J39: 150
I40: IG Story | J40: -
...

Sheet Sheet3
A1: October
A2: Tanggal | B2: Account Username | C2: Link | D2: Views | E2: Reach | F2: Likes | G2: Comments | H2: Saved | I2: Shares | J2: Profile Visits | K2: Replies | L2: Website Click | M2: Total Eng. | N2: ER (%)
A3: 28/10/2025 | B3: prythapramesthi | C3: https://www.instagram.com/p/DQWdPYukxqW/ | D3: 11768 | E3: 10193 | F3: 595 | G3: 30 | H3: 53 | I3: 54 | J3: - | K3: - | L3: - | M3: =SUM(F3:L3) -> 732 | N3: =M3/E3*100 -> 7.181399
A4: 28/10/2025 | B4: prythapramesthi | C4: https://www.tiktok.com/@prythaaa/video/7566238382657932551?_r=1&_t=ZS-902wPY3ZwOt | D4: 265 | E4: 0 | F4: 33 | G4: 6 | H4: 3 | I4: 2 | J4: - | K4: - | L4: - | M4: =SUM(F4:L4) -> 44 | N4: =M4/E4*100 -> #DIV/0!
A5: Total ER October | D5: =sum(D3:D4) -> 12033 | E5: =sum(E3:E4) -> 10193 | F5: =sum(F3:F4) -> 628 | G5: =sum(G3:G4) -> 36 | H5: =sum(H3:H4) -> 56 | I5: =sum(I3:I4) -> 56 | J5: =sum(J3:J4) -> 0 | K5: =sum(K3:K4) -> 0 | ... M5: =sum(M3:M4) -> 776 | N5: =M5/E5*100 -> 7.6130678
A8: November
A9: Tanggal | B9: Account Username | C9: Link | D9: Views | E9: Reach | F9: Likes | G9: Comments | H9: Saved | I9: Shares | J9: Profile Visits | K9: Replies | L9: Website Click | M9: Total Eng. | N9: ER (%)
A10: 45668 | B10: febrinaraamadhani | C10: https://www.instagram.com/reel/DQgXDoBD5W3/ | D10: 11073 | E10: 7150 | F10: 420 | G10: 11 | H10: 1 | I10: 25 | J10: - | K10: - | L10: - | M10: =SUM(F10:L10) -> 457 | N10: =M10/E10*100 -> 6.3916084
A11: 45727 | B11: novitanggrainie | C11: https://www.instagram.com/reel/DQmAQ-xk37j/?igsh=MWUyYTVkdzQ1eDFhMw== | D11: 66441 | E11: 85795 | F11: 526 | G11: 3 | H11: 36 | I11: 151 | J11: - | K11: - | L11: - | M11: =SUM(F11:L11) -> 716 | N11: =M11/E11*100 -> 0.83454747
A12: 45727 | B12: novitanggrainie | C12: https://vt.tiktok.com/ZSyDQSLFo/ | D12: 5638 | E12: - | F12: 118 | G12: 8 | H12: 59 | I12: 43 | J12: - | K12: - | L12: - | M12: =SUM(F12:L12) -> 228 | N12: =M12/E12*100 -> #VALUE!
A13: 45758 | B13: febrinaraamadhani | C13: https://www.instagram.com/reel/DQnfOawj5tN/ | D13: 2785 | E13: 1637 | F13: 336 | G13: 2 | H13: 3 | I13: 18 | J13: - | K13: - | L13: - | M13: =SUM(F13:L13) -> 359 | N13: =M13/E13*100 -> 21.93036
A14: 45788 | B14: febrinaraamadhani | C14: https://www.tiktok.com/@febrinaraamadhani/video/7569243186728537351 | D14: 276 | E14: - | F14: 39 | G14: - | H14: 3 | I14: 4 | J14: - | K14: - | L14: - | M14: =SUM(F14:L14) -> 46 | N14: =M14/E14*100 -> #VALUE!
A15: 45911 | B15: febrinaraamadhani | C15: https://www.tiktok.com/@febrinaraamadhani/video/7570556275973541138 | D15: 2248 | E15: - | F15: 139 | G15: - | H15: 5 | I15: 6 | J15: - | K15: - | L15: - | M15: =SUM(F15:L15) -> 150 | N15: =M15/E15*100 -> #VALUE!
A16: 15/11/2025 | B16: andinshifaaa | C16: https://www.instagram.com/reel/DRE3VtRkfaX/?igsh=MXQ1N3NxNnNyM200OQ%3D%3D | D16: 26181 | E16: 7800 | F16: 980 | G16: 26 | H16: 699 | I16: 829 | J16: - | K16: - | L16: - | M16: =SUM(F16:L16) -> 2534 | N16: =M16/E16*100 -> 32.487179
A17: 16/11/2025 | B17: andinshifaaa | C17: https://www.tiktok.com/@andsheblooms/video/7573177501309013266?_r=1&_t=ZS-91SmeFr6svl | D17: 14746 | E17: - | F17: 751 | G17: 18 | H17: 745 | I17: 206 | J17: - | K17: - | L17: - | M17: =SUM(F17:L17) -> 1720 | N17: =M17/E17*100 -> #VALUE!
A18: 22/11/2025 | B18: febrinaraamadhani | C18: https://www.instagram.com/reel/DRTkgOlDw9x/ | D18: 2301 | E18: 1283 | F18: 336 | G18: 5 | H18: 1 | I18: 22 | J18: - | K18: - | L18: - | M18: =SUM(F18:L18) -> 364 | N18: =M18/E18*100 -> 28.371005
A19: 23/11/2025 | B19: badaisamudrar | C19: https://www.instagram.com/reel/DRZhQ-9DVuf/?igsh=c3p5bXdmZ2RqMTli | D19: 4969 | E19: 3555 | F19: 156 | G19: 9 | H19: 22 | I19: 48 | J19: - | K19: - | L19: - | M19: =SUM(F19:L19) -> 235 | N19: =M19/E19*100 -> 6.6104079
A20: 23/11/2025 | B20: badaisamudrar | C20: https://www.tiktok.com/@badaisamudrar/video/7575896534823324935?_r=1&_t=ZS-91dh1cbkEGF | D20: 421 | E20: - | F20: 22 | G20: 2 | H20: 5 | I20: 3 | J20: - | K20: - | L20: - | M20: =SUM(F20:L20) -> 32 | N20: =M20/E20*100 -> #VALUE!
A21: 24/11/2025 | B21: febrinaraamadhani | C21: https://www.tiktok.com/@febrinaraamadhani/video/7576116429905251592 | D21: 12339 | E21: - | F21: 127 | G21: 2 | H21: 2 | I21: 8 | J21: - | K21: - | L21: - | M21: =SUM(F21:L21) -> 139 | N21: =M21/E21*100 -> #VALUE!
A22: Total ER November | D22: =sum(D10:D21) -> 149418 | E22: =sum(E10:E21) -> 107220 | F22: =sum(F10:F21) -> 3950 | G22: =sum(G10:G21) -> 86 | H22: =sum(H10:H21) -> 1581 | I22: =sum(I10:I21) -> 1363 | J22: =sum(J10:J21) -> 0 | K22: =sum(K10:K21) -> 0 | ... M22: =sum(M10:M21) -> 6980 | N22: =M22/E22*100 -> 6.5099795
A25: January
A26: Tanggal | B26: Account Username | C26: Link | D26: Views | E26: Reach | F26: Likes | G26: Comments | H26: Saved | I26: Shares | J26: Profile Visits | K26: Replies | L26: Website Click | M26: Total Eng. | N26: ER (%)
A27: 46034 | B27: badaisamudrar | C27: https://www.instagram.com/p/DTU_Nchk0j2/ | D27: 48266 | E27: 39381 | F27: 2146 | G27: 52 | H27: 1189 | I27: 1727 | J27: - | K27: - | L27: - | M27: =SUM(F27:L27) -> 5114 | N27: =M27/E27*100 -> 12.985958
A28: 46034 | B28: badaisamudrar | C28: https://www.tiktok.com/@badaisamudrar/video/7593924885374635282 | D28: 47849 | E28: - | F28: 4284 | G28: 39 | H28: 2135 | I28: 1208 | J28: - | K28: - | L28: - | M28: =SUM(F28:L28) -> 7666 | N28: =M28/E28*100 -> #VALUE!
A29: Total ER Jan | D29: =sum(D27:D28) -> 96115 | E29: =sum(E27:E28) -> 39381 | F29: =sum(F27:F28) -> 6430 | G29: =sum(G27:G28) -> 91 | H29: =sum(H27:H28) -> 3324 | I29: =sum(I27:I28) -> 2935 | M29: =sum(M27:M28) -> 12780 | N29: =M29/E29*100 -> 32.452198

Sheet Sheet4
A1: Placement | B1: Date | C1: Output Content | D1: QTY Post | E1: Link Post | F1: Engagement
F2: Views | G2: Reach/UV | H2: Likes | I2: Comments | J2: Saved | K2: Shares | L2: Profile Visits | M2: Replies | N2: Website Click/ Clicks | O2: Total Eng. | P2: ER
A3: APRIL
A4: Channel: DID
O5: =sum(H5:N5) -> 0 | P5: =O5/G5*100 -> #DIV/0!
A7: Channel: LI
O8: =sum(H8:N8) -> 0 | P8: =O8/G8*100 -> #DIV/0!
A10: Community Collab: Sidina Comunity
A11: KOL 1 - @resty.hartika | B11: 45772 | C11: IG Reels | D11: 1 | E11: https://www.instagram.com/p/DI1KAFAyC0q/ | F11: 3242 | G11: 775 | H11: 350 | I11: 41 | J11: 39 | K11: 38 | L11: - | M11: - | N11: - | O11: =SUM(H11:N11) -> 468 | P11: =O11/G11*100 -> 60.387097
A12: KOL 2 - @alizamaharani | B12: 45777 | C12: IG Reels | D12: 1 | E12: https://www.instagram.com/p/DJHQYITzjp6/ | F12: 15433 | G12: 2719 | H12: 1053 | I12: 41 | J12: 41 | K12: 941 | L12: - | M12: - | N12: - | O12: =SUM(H12:N12) -> 2076 | P12: =O12/G12*100 -> 76.3516
A13: Collab Post 1 @sidina | Hal kecil yang bikin Mompreneur Happy! | B13: 45770 | C13: IG Feed (Carousel) | D13: 1 | E13: https://www.instagram.com/p/DIyWCOFy_wq/?img_index=1 | F13: 1851 | G13: 1029 | H13: 406 | I13: 7 | J13: 0 | K13: 121 | L13: 33 | M13: 0 | N13: 0 | O13: =SUM(H13:N13) -> 567 | P13: =O13/G13*100 -> 55.102041
A14: Collab Post 2 @sidina | Tipe-tipe teman yang support pemilik UMKM | B14: 45775 | C14: IG Feed (Carousel) | D14: 1 | E14: https://www.instagram.com/p/DI_N_fKyn4z/?img_index=3 | F14: 2195 | G14: 1434 | H14: 397 | I14: 7 | J14: 3 | K14: 20 | L14: 28 | M14: 0 | N14: 0 | O14: =SUM(H14:N14) -> 455 | P14: =O14/G14*100 -> 31.729428
A16: MAY
A17: Channel: DID
A18: IGS SISBERDAYA | B18: 7-25 May | C18: IGS | F18: ='IGS May'!L76 -> #REF! | G18: ='IGS May'!M76 -> #REF! | H18: ='IGS May'!N76 -> #REF! | I18: 0 | J18: 0 | K18: ='IGS May'!O76 -> #REF! | L18: ='IGS May'!P76 -> #REF! | M18: ='IGS May'!Q76 -> #REF! | N18: ='IGS May'!R76 -> #REF! | O18: =sum(H18:N18) -> #REF! | P18: =O18/G18*100 -> #REF!
A19: Teaser #SISBERDAYA2025 - CTA Open Registration | B19: 45783 | C19: IG Reels | D19: 1 | E19: https://www.instagram.com/p/DJTLKnhStV7/ | F19: 3889 | G19: 2511 | H19: 446 | I19: 1 | J19: 4 | K19: 128 | L19: 0 | M19: 0 | N19: 0 | O19: =SUM(H19:N19) -> 579 | P19: =O19/G19*100 -> 23.058542
A20: KV OPEN REGISTRATION #SISBERDAYA2025 | B20: 45784 | C20: IG Feed (Single Post) - Ads | D20: 1 | E20: https://www.instagram.com/p/DJWZeuXscym/ | O20: =sum(H20:N20) -> 0 | P20: =O20/G20*100 -> #DIV/0!
A21: Event Highlight Press Conference #SISBERDAYA2025 | B21: 45787 | C21: IG Feed (Carousel Post) | D21: 1 | E21: https://www.instagram.com/p/DJeHhHkBAcr/?img_index=1 | F21: 3362 | G21: 1794 | H21: 549 | I21: 11 | J21: 21 | K21: 135 | L21: 48 | M21: 0 | N21: 6 | O21: =SUM(H21:N21) -> 770 | P21: =O21/G21*100 -> 42.920847
A22: #CeritaDANAM8s - DANA's Womenpreneur: Earthy Eats | B22: 45794 | C22: IG Feed (Carousel Post) | D22: 1 | E22: https://www.instagram.com/p/DJwJMxYva7J/?img_index=1 | F22: 5816 | G22: 2634 | H22: 540 | I22: 6 | J22: 3 | K22: 154 | L22: 63 | M22: 0 | N22: 3 | O22: =SUM(H22:N22) -> 769 | P22: =O22/G22*100 -> 29.19514
A23: #SisBerdaya | IG Reels - Event Highlight Press Conference | B23: 45795 | C23: IG Reels | D23: 1 | E23: https://www.instagram.com/p/DJyt4V-SA6Q/ | F23: 4022 | G23: 2392 | H23: 497 | I23: 4 | J23: 2 | K23: 106 | L23: 0 | M23: 0 | N23: 0 | O23: =SUM(H23:N23) -> 609 | P23: =O23/G23*100 -> 25.459866
A24: #SisBerdaya | Testimoni SISBERDAYA 2024 | B24: 45796 | C24: IG Feed (Carousel Post) | D24: 1 | E24: https://www.instagram.com/p/DJ1WJ6IB9iE/?img_index=1 | F24: 3226 | G24: 1558 | H24: 494 | I24: 16 | J24: 4 | K24: 152 | L24: 55 | M24: 0 | N24: 5 | O24: =SUM(H24:N24) -> 726 | P24: =O24/G24*100 -> 46.598203
A25: #TantanganDaysinDANA | #SISBERDAYA | B25: 45799 | C25: IG Feed (Single Post) - Ads | D25: 1 | E25: https://www.instagram.com/p/DJ9BDbzvRYk/ | F25: 286663 | G25: 144852 | H25: 895 | I25: 243 | J25: 108 | K25: 336 | L25: 2032 | M25: 0 | N25: 2171 | O25: =SUM(H25:N25) -> 5785 | P25: =O25/G25*100 -> 3.9937315
A26: Collab Post with dana.id: Info #SISBERDAYA | B26: 45800 | C26: IG Feed (Carousel Post) | D26: 1 | E26: https://www.instagram.com/p/DJ_S2sdPgVB/?img_index=1 | F26: 44354 | G26: 22547 | H26: 363 | I26: 336 | J26: 10 | K26: 8 | L26: 0 | M26: 0 | N26: 0 | O26: =sum(H26:N26) -> 717 | P26: =O26/G26*100 -> 3.1800239
A27: #SisBerdaya Closed Registration | B27: 45807 | C27: IG Feed (Carousel Post) | D27: 1 | E27: https://www.instagram.com/p/DKQxn5VqiTS/?img_index=1 | F27: 3637 | G27: 1933 | H27: 160 | I27: 19 | J27: 0 | K27: 5 | L27: 80 | M27: 0 | N27: 2 | O27: =SUM(H27:N27) -> 266 | P27: =O27/G27*100 -> 13.760993
A30: Channel: Linkedin
A31: KV OPEN REGISTRATION #SISBERDAYA2025 | B31: 45784 | C31: Feed post (Ads) | D31: 1 | E31: https://www.linkedin.com/feed/update/urn:li:activity:7325732628458803200 | F31: 287868 | G31: 2106 | H31: 59 | I31: 0 | J31: 0 | K31: 8 | L31: 0 | M31: 0 | N31: 2186 | O31: =sum(H31:N31) -> 2253 | P31: =O31/G31*100 -> 106.98006
A32: Event Highlight Press Conference #SISBERDAYA2025 | B32: 45787 | C32: Feed post | D32: 1 | E32: https://www.linkedin.com/posts/dana-indonesia_sisberdaya-2025-activity-7326923967867277312-L-ll?utm_source=share&utm_medium=member_desktop&rcm=ACoAABkzbf4BbS4hvKS0fGvtG1nVLRCgyurD254 | F32: 2035 | G32: 1281 | H32: 17 | I32: 0 | J32: 0 | K32: 1 | L32: 0 | M32: 0 | N32: 489 | O32: =sum(H32:N32) -> 507 | P32: =O32/G32*100 -> 39.578454
A33: #CeritaDANAM8s - DANA's Womenpreneur: Earthy Eats | B33: 45794 | C33: Feed post | D33: 1 | E33: https://www.linkedin.com/feed/update/urn:li:activity:7329460687460532224 | F33: 4672 | G33: 2520 | H33: 43 | I33: 2 | J33: 0 | K33: 3 | L33: 0 | M33: 0 | N33: 2748 | O33: =sum(H33:N33) -> 2796 | P33: =O33/G33*100 -> 110.95238
A34: #SisBerdaya | IG Reels - Event Highlight Press Conference | B34: 45795 | C34: Video Post | D34: 1 | E34: https://www.linkedin.com/feed/update/urn:li:activity:7329823070011961344 | F34: 33978 | G34: 898 | H34: 27 | I34: 0 | J34: 0 | K34: 1 | L34: 0 | M34: 0 | N34: 92 | O34: =sum(H34:N34) -> 120 | P34: =O34/G34*100 -> 13.363029
A35: LI Article #2 - Actionable Tips for Work-Life Harmony for Moms | B35: 45796 | C35: Feed post | D35: 1 | E35: https://www.linkedin.com/feed/update/urn:li:activity:7330204687842902016 | F35: 854 | G35: 553 | H35: 5 | I35: 0 | J35: 0 | K35: 0 | L35: 0 | M35: 0 | N35: 96 | O35: =sum(H35:N35) -> 101 | P35: =O35/G35*100 -> 18.264014
A36: #SisBerdaya | Testimoni SISBERDAYA 2024 | B36: 45800 | C36: Feed post | D36: 1 | E36: https://www.linkedin.com/feed/update/urn:li:activity:7331651767937499136/ | F36: 844 | G36: 335 | H36: 10 | I36: 0 | J36: 0 | K36: 0 | L36: 0 | M36: 0 | N36: 80 | O36: =sum(H36:N36) -> 90 | P36: =O36/G36*100 -> 26.865672
A37: Close Registration #SISBERDAYA | B37: 45807 | C37: Feed Post | D37: 1 | E37: https://www.linkedin.com/feed/update/urn:li:activity:7334035845991026689 | F37: 793 | G37: 585 | H37: 2 | I37: 0 | J37: 0 | K37: 0 | L37: 0 | M37: 0 | N37: 153 | O37: =sum(H37:N37) -> 155 | P37: =O37/G37*100 -> 26.495726
A39: Community Collab: Productive Mamas
A40: KOL 1 - Deysamosir | B40: 45797 | C40: IG Reels | D40: 1 | E40: https://www.instagram.com/p/DJ1Y5plPnEM/ | F40: 17306 | G40: 15804 | H40: 674 | I40: 30 | J40: 11 | K40: 333 | L40: 0 | M40: 0 | N40: 0 | O40: =SUM(H40:N40) -> 1048 | P40: =O40/G40*100 -> 6.6312326
A41: KOL 2 - Rika | C41: IG Reels | D41: 1 | E41: https://www.instagram.com/reel/DKLl3YAzdLA/?igsh=MXgxd3prcmdpd2x5Mw== | F41: 8243 | G41: 1150 | H41: 543 | I41: 70 | J41: 33 | K41: 1 | L41: 0 | M41: 0 | N41: 0 | O41: =SUM(H41:N41) -> 647 | P41: =O41/G41*100 -> 56.26087
A42: Collab Post 1 @productivemamas | Selain Skill, Womenpreneur Wajib Punya Mentor! | B42: 45800 | C42: IG Feed (Carousel Post) | D42: 1 | E42: https://www.instagram.com/p/DJ_l50iywFO/?img_index=1 | F42: 1767 | G42: 1001 | H42: 452 | I42: 6 | J42: 0 | K42: 107 | L42: 29 | M42: 0 | N42: 3 | O42: =SUM(H42:N42) -> 597 | P42: =O42/G42*100 -> 59.64036
A43: Collab Post 2 @productivemamas | Ibu-Ibu Produktif | B43: 45803 | C43: IG Feed (Carousel Post) | D43: 1 | E43: https://www.instagram.com/p/DKHURHyS01H/?img_index=1 | F43: 2844 | G43: 1943 | H43: 402 | I43: 9 | J43: 0 | K43: 5 | L43: 18 | M43: 0 | N43: 1 | O43: =SUM(H43:N43) -> 435 | P43: =O43/G43*100 -> 22.38806
A45: JUNE
A46: Channel: DID
A47: IGS SISBERDAYA | B47: 1-30 June | C47: IGS | F47: ='IGS June'!L75 -> #REF! | G47: ='IGS June'!M75 -> #REF! | H47: ='IGS June'!N75 -> #REF! | I47: 0 | J47: 0 | K47: 0 | L47: ='IGS June'!Q75 -> #REF! | M47: ='IGS June'!R75 -> #REF! | N47: ='IGS June'!S75 -> #REF! | O47: =SUM(H47:N47) -> #REF! | P47: =O47/G47*100 -> #REF!
...
